<?xml version="1.0" encoding="UTF-8"?>
<!-- Generated by org.testng.reporters.JUnitXMLReporter -->
<testsuite hostname="LXG-PC" name="192.168.56.102:5555" tests="2" failures="1" timestamp="30 Aug 2016 16:12:34 GMT" time="0.03" errors="0">
  <testcase name="test" time="0.011" classname="cn.crazy.appium.network.study.Study5"/>
  <testcase name="test1" time="0.004" classname="cn.crazy.appium.network.study.Study5">
    <failure type="java.lang.AssertionError" message="错了">
      <![CDATA[java.lang.AssertionError: 错了
	at cn.crazy.appium.network.study.Study5.test1(Study5.java:17)
	at java.util.concurrent.FutureTask.run(FutureTask.java:266)
	at java.util.concurrent.ThreadPoolExecutor.runWorker(ThreadPoolExecutor.java:1142)
	at java.util.concurrent.ThreadPoolExecutor$Worker.run(ThreadPoolExecutor.java:617)
	at java.lang.Thread.run(Thread.java:745)
... Removed 17 stack frames]]>
    </failure>
  </testcase> <!-- test1 -->
</testsuite> <!-- 192.168.56.102:5555 -->
