<?xml version="1.0" encoding="UTF-8"?>
<testng-results skipped="1" failed="0" total="1" passed="0">
  <reporter-output>
  </reporter-output>
  <suite name="Suite" duration-ms="4308" started-at="2016-12-27T07:36:27Z" finished-at="2016-12-27T07:36:31Z">
    <groups>
    </groups>
    <test name="da926816" duration-ms="4308" started-at="2016-12-27T07:36:27Z" finished-at="2016-12-27T07:36:31Z">
      <class name="cn.crazy.appium.testcases.ZhiHuTest">
        <test-method status="PASS" signature="beforeClass(java.lang.String, java.lang.String)[pri:0, instance:cn.crazy.appium.testcases.ZhiHuTest@48b6434f]" name="beforeClass" is-config="true" duration-ms="4279" started-at="2016-12-27T15:36:27Z" finished-at="2016-12-27T15:36:31Z">
          <params>
            <param index="0">
              <value>
                <![CDATA[127.0.0.1:62001]]>
              </value>
            </param>
            <param index="1">
              <value>
                <![CDATA[4491]]>
              </value>
            </param>
          </params>
          <reporter-output>
          </reporter-output>
        </test-method> <!-- beforeClass -->
        <test-method status="SKIP" signature="t001_login(java.lang.String, java.lang.String, java.lang.String, java.lang.String, java.lang.String, java.lang.String)[pri:0, instance:cn.crazy.appium.testcases.ZhiHuTest@48b6434f]" name="t001_login" duration-ms="0" started-at="2016-12-27T15:36:31Z" data-provider="loginData" finished-at="2016-12-27T15:36:31Z">
          <exception class="java.lang.RuntimeException">
            <message>
              <![CDATA[java.io.FileNotFoundException: C:\Users\LXG\Desktop\test.xlsx (系统找不到指定的路径。)]]>
            </message>
            <full-stacktrace>
              <![CDATA[java.lang.RuntimeException: java.io.FileNotFoundException: C:\Users\LXG\Desktop\test.xlsx (系统找不到指定的路径。)
	at org.testng.internal.MethodInvocationHelper.invokeDataProvider(MethodInvocationHelper.java:163)
	at org.testng.internal.Parameters.handleParameters(Parameters.java:430)
	at org.testng.internal.Invoker.handleParameters(Invoker.java:1274)
	at org.testng.internal.Invoker.createParameters(Invoker.java:989)
	at org.testng.internal.Invoker.invokeTestMethods(Invoker.java:1079)
	at org.testng.internal.TestMethodWorker.invokeTestMethods(TestMethodWorker.java:129)
	at org.testng.internal.TestMethodWorker.run(TestMethodWorker.java:112)
	at org.testng.TestRunner.privateRun(TestRunner.java:782)
	at org.testng.TestRunner.run(TestRunner.java:632)
	at org.testng.SuiteRunner.runTest(SuiteRunner.java:366)
	at org.testng.SuiteRunner.access$000(SuiteRunner.java:39)
	at org.testng.SuiteRunner$SuiteWorker.run(SuiteRunner.java:400)
	at org.testng.internal.thread.ThreadUtil$2.call(ThreadUtil.java:64)
	at java.util.concurrent.FutureTask.run(Unknown Source)
	at java.util.concurrent.ThreadPoolExecutor.runWorker(Unknown Source)
	at java.util.concurrent.ThreadPoolExecutor$Worker.run(Unknown Source)
	at java.lang.Thread.run(Unknown Source)
Caused by: java.io.FileNotFoundException: C:\Users\LXG\Desktop\test.xlsx (系统找不到指定的路径。)
	at java.io.FileInputStream.open(Native Method)
	at java.io.FileInputStream.<init>(Unknown Source)
	at cn.crazy.appium.datadriver.ExcelUtil.getTestData(ExcelUtil.java:134)
	at cn.crazy.appium.testcases.ZhiHuTest.loginData(ZhiHuTest.java:51)
	at sun.reflect.NativeMethodAccessorImpl.invoke0(Native Method)
	at sun.reflect.NativeMethodAccessorImpl.invoke(Unknown Source)
	at sun.reflect.DelegatingMethodAccessorImpl.invoke(Unknown Source)
	at java.lang.reflect.Method.invoke(Unknown Source)
	at org.testng.internal.MethodInvocationHelper.invokeMethod(MethodInvocationHelper.java:86)
	at org.testng.internal.MethodInvocationHelper.invokeDataProvider(MethodInvocationHelper.java:137)
	... 16 more
]]>
            </full-stacktrace>
          </exception> <!-- java.lang.RuntimeException -->
          <reporter-output>
          </reporter-output>
        </test-method> <!-- t001_login -->
        <test-method status="FAIL" signature="afterClass()[pri:0, instance:cn.crazy.appium.testcases.ZhiHuTest@48b6434f]" name="afterClass" is-config="true" duration-ms="0" started-at="2016-12-27T15:36:31Z" finished-at="2016-12-27T15:36:31Z">
          <exception class="java.lang.NullPointerException">
            <full-stacktrace>
              <![CDATA[java.lang.NullPointerException
	at cn.crazy.appium.testcases.ZhiHuTest.afterClass(ZhiHuTest.java:147)
	at sun.reflect.NativeMethodAccessorImpl.invoke0(Native Method)
	at sun.reflect.NativeMethodAccessorImpl.invoke(Unknown Source)
	at sun.reflect.DelegatingMethodAccessorImpl.invoke(Unknown Source)
	at java.lang.reflect.Method.invoke(Unknown Source)
	at org.testng.internal.MethodInvocationHelper.invokeMethod(MethodInvocationHelper.java:86)
	at org.testng.internal.Invoker.invokeConfigurationMethod(Invoker.java:514)
	at org.testng.internal.Invoker.invokeConfigurations(Invoker.java:215)
	at org.testng.internal.Invoker.invokeConfigurations(Invoker.java:142)
	at org.testng.internal.TestMethodWorker.invokeAfterClassMethods(TestMethodWorker.java:232)
	at org.testng.internal.TestMethodWorker.run(TestMethodWorker.java:115)
	at org.testng.TestRunner.privateRun(TestRunner.java:782)
	at org.testng.TestRunner.run(TestRunner.java:632)
	at org.testng.SuiteRunner.runTest(SuiteRunner.java:366)
	at org.testng.SuiteRunner.access$000(SuiteRunner.java:39)
	at org.testng.SuiteRunner$SuiteWorker.run(SuiteRunner.java:400)
	at org.testng.internal.thread.ThreadUtil$2.call(ThreadUtil.java:64)
	at java.util.concurrent.FutureTask.run(Unknown Source)
	at java.util.concurrent.ThreadPoolExecutor.runWorker(Unknown Source)
	at java.util.concurrent.ThreadPoolExecutor$Worker.run(Unknown Source)
	at java.lang.Thread.run(Unknown Source)
]]>
            </full-stacktrace>
          </exception> <!-- java.lang.NullPointerException -->
          <reporter-output>
          </reporter-output>
        </test-method> <!-- afterClass -->
      </class> <!-- cn.crazy.appium.testcases.ZhiHuTest -->
    </test> <!-- da926816 -->
  </suite> <!-- Suite -->
</testng-results>
